Workbook

Sheet I 2024
A1: Resultado | B1: 45292 | C1: 45323 | D1: 45352 | E1: 45383 | F1: 45413 | G1: 45444 | H1: 45474 | I1: 45505 | J1: 45536 | K1: 45566 | L1: 45597 | M1: 45627 | N1: Total
A2: Resultado | N2: Total
A3: Receita operacional bruta | B3: 450429 | C3: 0 | D3: 0 | E3: 0 | F3: 0 | G3: 0 | H3: 0 | I3: 0 | J3: 0 | K3: 0 | L3: 0 | M3: 0 | N3: 450429
A4: [-] 10 - Receita | B4: 450429 | C4: 0 | D4: 0 | E4: 0 | F4: 0 | G4: 0 | H4: 0 | I4: 0 | J4: 0 | K4: 0 | L4: 0 | M4: 0 | N4: 450429
A5: 10.01 - Receita com produto | B5: 449858 | C5: 0 | D5: 0 | E5: 0 | F5: 0 | G5: 0 | H5: 0 | I5: 0 | J5: 0 | K5: 0 | L5: 0 | M5: 0 | N5: 449858
A6: 10.03 - Outras Receitas | B6: 571 | C6: 0 | D6: 0 | E6: 0 | F6: 0 | G6: 0 | H6: 0 | I6: 0 | J6: 0 | K6: 0 | L6: 0 | M6: 0 | N6: 571
A7: Custos de venda | B7: -11749 | C7: 0 | D7: 0 | E7: 0 | F7: 0 | G7: 0 | H7: 0 | I7: 0 | J7: 0 | K7: 0 | L7: 0 | M7: 0 | N7: -11749
A8: [-] 20 - Impostos sobre a receita | B8: -11749 | C8: 0 | D8: 0 | E8: 0 | F8: 0 | G8: 0 | H8: 0 | I8: 0 | J8: 0 | K8: 0 | L8: 0 | M8: 0 | N8: -11749
A9: 20.04 - ICMS - ST | B9: -11749 | C9: 0 | D9: 0 | E9: 0 | F9: 0 | G9: 0 | H9: 0 | I9: 0 | J9: 0 | K9: 0 | L9: 0 | M9: 0 | N9: -11749
A10: 21 - Crédito de impostos | B10: 0 | C10: 0 | D10: 0 | E10: 0 | F10: 0 | G10: 0 | H10: 0 | I10: 0 | J10: 0 | K10: 0 | L10: 0 | M10: 0 | N10: 0
A11: 22 - Repasse aos distribuidores | B11: 0 | C11: 0 | D11: 0 | E11: 0 | F11: 0 | G11: 0 | H11: 0 | I11: 0 | J11: 0 | K11: 0 | L11: 0 | M11: 0 | N11: 0
A12: 55 - Devolução de Terceiros | B12: 0 | C12: 0 | D12: 0 | E12: 0 | F12: 0 | G12: 0 | H12: 0 | I12: 0 | J12: 0 | K12: 0 | L12: 0 | M12: 0 | N12: 0
A13: ( = ) Receita operacional líquida | B13: 438680 | C13: 0 | D13: 0 | E13: 0 | F13: 0 | G13: 0 | H13: 0 | I13: 0 | J13: 0 | K13: 0 | L13: 0 | M13: 0 | N13: 438680
A14: Receita operacional líquida ( % ) | B14: 0.97 | C14: % | D14: % | E14: % | F14: % | G14: % | H14: % | I14: % | J14: % | K14: % | L14: % | M14: % | N14: 0.97
A15: Custos Operacionais Variáveis | B15: -269834 | C15: 0 | D15: 0 | E15: 0 | F15: 0 | G15: 0 | H15: 0 | I15: 0 | J15: 0 | K15: 0 | L15: 0 | M15: 0 | N15: -269834
A16: [-] 29 - Despesas com Pessoal - Operacional | B16: -25339 | C16: 0 | D16: 0 | E16: 0 | F16: 0 | G16: 0 | H16: 0 | I16: 0 | J16: 0 | K16: 0 | L16: 0 | M16: 0 | N16: -25339
A17: 29.01 - Operacional - Salário líquido | B17: -6816 | C17: 0 | D17: 0 | E17: 0 | F17: 0 | G17: 0 | H17: 0 | I17: 0 | J17: 0 | K17: 0 | L17: 0 | M17: 0 | N17: -6816
A18: 29.02 - Operacional - 13o salário | B18: -159 | C18: 0 | D18: 0 | E18: 0 | F18: 0 | G18: 0 | H18: 0 | I18: 0 | J18: 0 | K18: 0 | L18: 0 | M18: 0 | N18: -159
A19: 29.06 - Operacional - INSS | B19: -15675 | C19: 0 | D19: 0 | E19: 0 | F19: 0 | G19: 0 | H19: 0 | I19: 0 | J19: 0 | K19: 0 | L19: 0 | M19: 0 | N19: -15675
A20: 29.17 - Operacional - Refeitório | B20: -782 | C20: 0 | D20: 0 | E20: 0 | F20: 0 | G20: 0 | H20: 0 | I20: 0 | J20: 0 | K20: 0 | L20: 0 | M20: 0 | N20: -782
A21: 29.19 - Operacional - Horas Extras | B21: -1907 | C21: 0 | D21: 0 | E21: 0 | F21: 0 | G21: 0 | H21: 0 | I21: 0 | J21: 0 | K21: 0 | L21: 0 | M21: 0 | N21: -1907
A22: [-] 30 - Insumos de Produção | B22: -237263 | C22: 0 | D22: 0 | E22: 0 | F22: 0 | G22: 0 | H22: 0 | I22: 0 | J22: 0 | K22: 0 | L22: 0 | M22: 0 | N22: -237263
A23: 30.01 - Matérias primas | B23: -138506 | C23: 0 | D23: 0 | E23: 0 | F23: 0 | G23: 0 | H23: 0 | I23: 0 | J23: 0 | K23: 0 | L23: 0 | M23: 0 | N23: -138506
A24: 30.02 - Embalagens | B24: -98757 | C24: 0 | D24: 0 | E24: 0 | F24: 0 | G24: 0 | H24: 0 | I24: 0 | J24: 0 | K24: 0 | L24: 0 | M24: 0 | N24: -98757
A25: [-] 33 - Custos Indiretos de Fabricação | B25: -7232 | C25: 0 | D25: 0 | E25: 0 | F25: 0 | G25: 0 | H25: 0 | I25: 0 | J25: 0 | K25: 0 | L25: 0 | M25: 0 | N25: -7232
A26: 33.01 - Energia | B26: -596 | C26: 0 | D26: 0 | E26: 0 | F26: 0 | G26: 0 | H26: 0 | I26: 0 | J26: 0 | K26: 0 | L26: 0 | M26: 0 | N26: -596
... A33: ( = ) Resultado Bruto | B33: 168846 | C33: 0 | D33: 0 | E33: 0 | F33: 0 | G33: 0 | H33: 0 | I33: 0 | J33: 0 | K33: 0 | L33: 0 | M33: 0 | N33: 168846
A34: Resultado Bruto ( % ) | B34: 0.37 | C34: % | D34: % | E34: % | F34: % | G34: % | H34: % | I34: % | J34: % | K34: % | L34: % | M34: % | N34: 0.37
A35: Despesas Operacionais | Administração | B35: -2619 | C35: 0 | D35: 0 | E35: 0 | F35: 0 | G35: 0 | H35: 0 | I35: 0 | J35: 0 | K35: 0 | L35: 0 | M35: 0 | N35: -2619
A36: [-] 41 - Despesas com Pessoal - Administração | B36: -847 | C36: 0 | D36: 0 | E36: 0 | F36: 0 | G36: 0 | H36: 0 | I36: 0 | J36: 0 | K36: 0 | L36: 0 | M36: 0 | N36: -847
A37: 41.07 - Administrativo - FGTS | B37: -847 | C37: 0 | D37: 0 | E37: 0 | F37: 0 | G37: 0 | H37: 0 | I37: 0 | J37: 0 | K37: 0 | L37: 0 | M37: 0 | N37: -847
A38: [-] 42 - Infra-estrutura Administrativa | B38: -99 | C38: 0 | D38: 0 | E38: 0 | F38: 0 | G38: 0 | H38: 0 | I38: 0 | J38: 0 | K38: 0 | L38: 0 | M38: 0 | N38: -99
A39: 42.03 - Internet | B39: -99 | C39: 0 | D39: 0 | E39: 0 | F39: 0 | G39: 0 | H39: 0 | I39: 0 | J39: 0 | K39: 0 | L39: 0 | M39: 0 | N39: -99
A40: [-] 43 - Serviços de apoio à operação | B40: -1673 | C40: 0 | D40: 0 | E40: 0 | F40: 0 | G40: 0 | H40: 0 | I40: 0 | J40: 0 | K40: 0 | L40: 0 | M40: 0 | N40: -1673
A41: 43.10 - Softwares de gestão | B41: -1566 | C41: 0 | D41: 0 | E41: 0 | F41: 0 | G41: 0 | H41: 0 | I41: 0 | J41: 0 | K41: 0 | L41: 0 | M41: 0 | N41: -1566
A42: 43.12 - Tarifas | B42: -107 | C42: 0 | D42: 0 | E42: 0 | F42: 0 | G42: 0 | H42: 0 | I42: 0 | J42: 0 | K42: 0 | L42: 0 | M42: 0 | N42: -107
A43: 44 - Transporte próprio da Administração | B43: 0 | C43: 0 | D43: 0 | E43: 0 | F43: 0 | G43: 0 | H43: 0 | I43: 0 | J43: 0 | K43: 0 | L43: 0 | M43: 0 | N43: 0
A44: 45 - Despesas administrativas | B44: 0 | C44: 0 | D44: 0 | E44: 0 | F44: 0 | G44: 0 | H44: 0 | I44: 0 | J44: 0 | K44: 0 | L44: 0 | M44: 0 | N44: 0
A45: 46 - Manutenção Administrativa | B45: 0 | C45: 0 | D45: 0 | E45: 0 | F45: 0 | G45: 0 | H45: 0 | I45: 0 | J45: 0 | K45: 0 | L45: 0 | M45: 0 | N45: 0
A46: 47 - Impostos | B46: 0 | C46: 0 | D46: 0 | E46: 0 | F46: 0 | G46: 0 | H46: 0 | I46: 0 | J46: 0 | K46: 0 | L46: 0 | M46: 0 | N46: 0
...

Sheet PL.C
B3: Classf. | C3: Nome da conta | D3: Tipo | E3: Natureza | F3: Grupo de conta | G3: Função no controle de reembolso de despesas | H3: Ativo
B4: 10 | C4: Receita | D4: Sintética | E4: --- | F4: Receita operacional bruta | G4: --- | H4: sim
B5: 10.01 | C5: Receita com produto | D5: Analítica | E5: Entrada | F5: Receita operacional bruta | G5: --- | H5: sim
B6: 10.02 | C6: Receita com serviço | D6: Analítica | E6: Entrada | F6: Receita operacional bruta | G6: --- | H6: sim
B7: 10.03 | C7: Outras Receitas | D7: Analítica | E7: Entrada | F7: Receita operacional bruta | G7: Nenhuma | H7: sim
B8: 10.04 | C8: Estorno de Produto | D8: Analítica | E8: Saída | F8: Receita operacional bruta | G8: Nenhuma | H8: sim
B9: 10.06 | C9: Devolução de produto | D9: Analítica | E9: Saída | F9: Receita operacional bruta | G9: Nenhuma | H9: sim
B10: 10.07 | C10: Adiantamento de despesas de cliente | D10: Analítica | E10: Saída | F10: Receita operacional bruta | G10: Nenhuma | H10: sim
B11: 10.08 | C11: Devolução de Recebimento | D11: Analítica | E11: Saída | F11: Receita operacional bruta | G11: Nenhuma | H11: sim
B12: 20 | C12: Impostos sobre a receita | D12: Sintética | E12: --- | F12: Custos de venda | G12: --- | H12: sim
B13: 20.01 | C13: ICMS | D13: Analítica | E13: Saída | F13: Custos de venda | G13: --- | H13: sim
B14: 20.04 | C14: ICMS - ST | D14: Analítica | E14: Saída | F14: Custos de venda | G14: Nenhuma | H14: sim
B15: 20.05 | C15: DIFAL | D15: Analítica | E15: Saída | F15: Custos de venda | G15: Nenhuma | H15: sim
B16: 21 | C16: Crédito de impostos | D16: Sintética | E16: --- | F16: Custos de venda | G16: --- | H16: sim
B17: 21.01 | C17: ICMS | D17: Analítica | E17: Entrada | F17: Custos de venda | G17: --- | H17: sim
B18: 21.02 | C18: IPI | D18: Analítica | E18: Entrada | F18: Custos de venda | G18: --- | H18: sim
B19: 21.03 | C19: ISS | D19: Analítica | E19: Entrada | F19: Custos de venda | G19: --- | H19: sim
B20: 22 | C20: Repasse aos distribuidores | D20: Sintética | E20: --- | F20: Custos de venda | G20: Nenhuma | H20: sim
B21: 22.01 | C21: Repasse Distribuidores | D21: Analítica | E21: Saída | F21: Custos de venda | G21: Nenhuma | H21: sim
B22: 29 | C22: Despesas com Pessoal - Operacional | D22: Sintética | E22: --- | F22: Custos Operacionais Variáveis | G22: Nenhuma | H22: sim
B23: 29.01 | C23: Operacional - Salário líquido | D23: Analítica | E23: Saída | F23: Custos Operacionais Variáveis | G23: --- | H23: sim
B24: 29.02 | C24: Operacional - 13o salário | D24: Analítica | E24: Saída | F24: Custos Operacionais Variáveis | G24: --- | H24: sim
B25: 29.03 | C25: Operacional - Férias | D25: Analítica | E25: Saída | F25: Custos Operacionais Variáveis | G25: --- | H25: sim
B26: 29.04 | C26: Operacional - Rescisão | D26: Analítica | E26: Saída | F26: Custos Operacionais Variáveis | G26: --- | H26: sim
B27: 29.05 | C27: Operacional - Multa rescisória | D27: Analítica | E27: Saída | F27: Custos Operacionais Variáveis | G27: --- | H27: sim
B28: 29.06 | C28: Operacional - INSS | D28: Analítica | E28: Saída | F28: Custos Operacionais Variáveis | G28: --- | H28: sim
B29: 29.07 | C29: Operacional - FGTS | D29: Analítica | E29: Saída | F29: Custos Operacionais Variáveis | G29: --- | H29: sim
B30: 29.08 | C30: Operacional - IRRF | D30: Analítica | E30: Saída | F30: Custos Operacionais Variáveis | G30: --- | H30: sim
B31: 29.09 | C31: Operacional - Vale refeição | D31: Analítica | E31: Saída | F31: Custos Operacionais Variáveis | G31: --- | H31: sim
B32: 29.10 | C32: Operacional - Vale alimentação | D32: Analítica | E32: Saída | F32: Custos Operacionais Variáveis | G32: --- | H32: sim
B33: 29.11 | C33: Operacional - Vale transporte | D33: Analítica | E33: Saída | F33: Custos Operacionais Variáveis | G33: --- | H33: sim
B34: 29.12 | C34: Operacional - Plano de saúde | D34: Analítica | E34: Saída | F34: Custos Operacionais Variáveis | G34: --- | H34: sim
... B41: 29.19 | C41: Operacional - Horas Extras | D41: Analítica | E41: Saída | F41: Custos Operacionais Variáveis | G41: Nenhuma | H41: sim
B42: 30 | C42: Insumos de Produção | D42: Sintética | E42: --- | F42: Custos Operacionais Variáveis | G42: --- | H42: sim
B43: 30.01 | C43: Matérias primas | D43: Analítica | E43: Saída | F43: Custos Operacionais Variáveis | G43: --- | H43: sim
B44: 30.02 | C44: Embalagens | D44: Analítica | E44: Saída | F44: Custos Operacionais Variáveis | G44: --- | H44: sim
B45: 31 | C45: Materiais de consumo operacionais | D45: Sintética | E45: --- | F45: Custos Operacionais Fixos | G45: Nenhuma | H45: sim
B46: 31.02 | C46: Produtos de higiene | D46: Analítica | E46: Saída | F46: Custos Operacionais Fixos | G46: Nenhuma | H46: sim
B47: 31.04 | C47: Equipamentos de Proteção Individual | D47: Analítica | E47: Saída | F47: Custos Operacionais Fixos | G47: Nenhuma | H47: sim
B48: 31.05 | C48: Uniformes | D48: Analítica | E48: Saída | F48: Custos Operacionais Fixos | G48: Nenhuma | H48: sim
...

Sheet I
A1: colar na célula A2 | B1: 45658 | C1: 45689 | D1: 45717 | E1: 45748 | F1: 45778 | G1: 45809 | H1: 45839 | I1: 45870 | J1: 45901 | K1: 45931 | L1: 45962 | M1: 45992 | N1: Total
A2: Receita operacional bruta | B2: 1385199 | C2: 1267113 | D2: 1314151 | E2: 1590579 | F2: 1497226 | G2: 1483637 | H2: 1883540 | I2: 1534163 | J2: 1652451 | K2: 1528370 | L2: 1348686 | M2: 1782991 | N2: 18268112
A3: [-] 10 - Receita | B3: 1385199 | C3: 1267113 | D3: 1314151 | E3: 1590579 | F3: 1497226 | G3: 1483637 | H3: 1883540 | I3: 1534163 | J3: 1652451 | K3: 1528370 | L3: 1348686 | M3: 1782991 | N3: 18268112
A4: 10.01 - Receita com produto | B4: 1379860 | C4: 1267464 | D4: 1314099 | E4: 1583657 | F4: 1498153 | G4: 1477480 | H4: 1883211 | I4: 1532324 | J4: 1649142 | K4: 1528791 | L4: 1348698 | M4: 1781131 | N4: 18244016
A5: 10.02 - Receita com serviço | B5: 0 | C5: 0 | D5: 0 | E5: 0 | F5: 0 | G5: 0 | H5: 0 | I5: 0 | J5: 85 | K5: 0 | L5: 0 | M5: 0 | N5: 85
A6: 10.03 - Outras Receitas | B6: 6982 | C6: 4142 | D6: 362 | E6: 7275 | F6: 0 | G6: 6264 | H6: 2807 | I6: 2053 | J6: 3353 | K6: 0 | L6: 0 | M6: 3540 | N6: 36782
A7: 10.06 - Devolução de produto | B7: -1643 | C7: -4493 | D7: -310 | E7: -353 | F7: -927 | G7: -107 | H7: -133 | I7: -168 | J7: -130 | K7: -114 | L7: -12 | M7: -1680 | N7: -10075
A8: 10.08 - Devolução de Recebimento | B8: 0 | C8: 0 | D8: 0 | E8: 0 | F8: 0 | G8: 0 | H8: -2343 | I8: -45 | J8: 0 | K8: -306 | L8: 0 | M8: 0 | N8: -2695
A9: Custos de venda | B9: -76353 | C9: -61825 | D9: -84284 | E9: -86087 | F9: -94571 | G9: -80879 | H9: -102307 | I9: -101456 | J9: -91951 | K9: -81174 | L9: -103162 | M9: -105589 | N9: -1069643
A10: [-] 20 - Impostos sobre a receita | B10: -76593 | C10: -58280 | D10: -82822 | E10: -84256 | F10: -92783 | G10: -80722 | H10: -100812 | I10: -100525 | J10: -89559 | K10: -81174 | L10: -101070 | M10: -105589 | N10: -1054190
A11: 20.01 - ICMS | B11: -20159 | C11: -25180 | D11: -29078 | E11: -23991 | F11: -29468 | G11: -14431 | H11: -31227 | I11: -35068 | J11: -27813 | K11: -22114 | L11: -38319 | M11: -36335 | N11: -333189
A12: 20.04 - ICMS - ST | B12: -56433 | C12: -33100 | D12: -53743 | E12: -60264 | F12: -63315 | G12: -66290 | H12: -69584 | I12: -65456 | J12: -61745 | K12: -59060 | L12: -62750 | M12: -69254 | N12: -721001
A13: 21 - Crédito de impostos | B13: 0 | C13: 0 | D13: 0 | E13: 0 | F13: 0 | G13: 0 | H13: 0 | I13: 0 | J13: 0 | K13: 0 | L13: 0 | M13: 0 | N13: 0
... A180: Variação de caixa ( % ) | B180: -0.04 | C180: -0.12 | D180: 0.09 | E180: 0.13 | F180: 0.15 | G180: 0.03 | H180: 0.15 | I180: 0.31 | J180: 0.09 | K180: 0.04 | L180: 0.1 | M180: 0.13 | N180: 0.09

Sheet D
B2: 44562 | C2: 44593 | D2: 44621 | E2: 44652 | F2: 44682 | G2: 44713 | H2: 44743 | I2: 44774 | J2: 44805 | K2: 44835 | L2: 44866 | M2: 44896 | P2: 45658 | Q2: 45689 | R2: 45717 | S2: 45748 | T2: 45778 | U2: 45809 | V2: 45839 | W2: 45870 | X2: 45901 | Y2: 45931 | Z2: 45962 | AA2: 45992
A3: =IFERROR((IF(((IFERROR((FIND(".",I!A1)),0))>1),(MID(I!A1,((FIND(".",I!A1))-2),5)),(MID(I!A1,((FIND(" - ",I!A1))-2),2)))),"-") | B3: =IFERROR(IF($A3="-","null",I!B1),"null") | C3: =IFERROR(IF($A3="-","null",I!C1),"null") | D3: =IFERROR(IF($A3="-","null",I!D1),"null") | E3: =IFERROR(IF($A3="-","null",I!E1),"null") | F3: =IFERROR(IF($A3="-","null",I!F1),"null") | G3: =IFERROR(IF($A3="-","null",I!G1),"null") | H3: =IFERROR(IF($A3="-","null",I!H1),"null") | I3: =IFERROR(IF($A3="-","null",I!I1),"null") | ... M3: =IFERROR(IF($A3="-","null",I!M1),"null") | O3: 10.01 | P3: =SUMIFS(B:B,$A:$A,$O3) | Q3: =SUMIFS(C:C,$A:$A,$O3) | R3: =SUMIFS(D:D,$A:$A,$O3) | S3: =SUMIFS(E:E,$A:$A,$O3) | T3: =SUMIFS(F:F,$A:$A,$O3) | U3: =SUMIFS(G:G,$A:$A,$O3) | V3: =SUMIFS(H:H,$A:$A,$O3) | W3: =SUMIFS(I:I,$A:$A,$O3) | X3: =SUMIFS(J:J,$A:$A,$O3) | Y3: =SUMIFS(K:K,$A:$A,$O3) | Z3: =SUMIFS(L:L,$A:$A,$O3) | AA3: =SUMIFS(M:M,$A:$A,$O3)
A4: =IFERROR((IF(((IFERROR((FIND(".",I!A2)),0))>1),(MID(I!A2,((FIND(".",I!A2))-2),5)),(MID(I!A2,((FIND(" - ",I!A2))-2),2)))),"-") | B4: =IFERROR(IF($A4="-","null",I!B2),"null") | C4: =IFERROR(IF($A4="-","null",I!C2),"null") | D4: =IFERROR(IF($A4="-","null",I!D2),"null") | E4: =IFERROR(IF($A4="-","null",I!E2),"null") | F4: =IFERROR(IF($A4="-","null",I!F2),"null") | G4: =IFERROR(IF($A4="-","null",I!G2),"null") | H4: =IFERROR(IF($A4="-","null",I!H2),"null") | I4: =IFERROR(IF($A4="-","null",I!I2),"null") | ... M4: =IFERROR(IF($A4="-","null",I!M2),"null") | O4: 10.02 | P4: =SUMIFS(B:B,$A:$A,$O4) | Q4: =SUMIFS(C:C,$A:$A,$O4) | R4: =SUMIFS(D:D,$A:$A,$O4) | S4: =SUMIFS(E:E,$A:$A,$O4) | T4: =SUMIFS(F:F,$A:$A,$O4) | U4: =SUMIFS(G:G,$A:$A,$O4) | V4: =SUMIFS(H:H,$A:$A,$O4) | W4: =SUMIFS(I:I,$A:$A,$O4) | X4: =SUMIFS(J:J,$A:$A,$O4) | Y4: =SUMIFS(K:K,$A:$A,$O4) | Z4: =SUMIFS(L:L,$A:$A,$O4) | AA4: =SUMIFS(M:M,$A:$A,$O4)
A5: =IFERROR((IF(((IFERROR((FIND(".",I!A3)),0))>1),(MID(I!A3,((FIND(".",I!A3))-2),5)),(MID(I!A3,((FIND(" - ",I!A3))-2),2)))),"-") | B5: =IFERROR(IF($A5="-","null",I!B3),"null") | C5: =IFERROR(IF($A5="-","null",I!C3),"null") | D5: =IFERROR(IF($A5="-","null",I!D3),"null") | E5: =IFERROR(IF($A5="-","null",I!E3),"null") | F5: =IFERROR(IF($A5="-","null",I!F3),"null") | G5: =IFERROR(IF($A5="-","null",I!G3),"null") | H5: =IFERROR(IF($A5="-","null",I!H3),"null") | I5: =IFERROR(IF($A5="-","null",I!I3),"null") | ... M5: =IFERROR(IF($A5="-","null",I!M3),"null") | O5: 10.03 | P5: =SUMIFS(B:B,$A:$A,$O5) | Q5: =SUMIFS(C:C,$A:$A,$O5) | R5: =SUMIFS(D:D,$A:$A,$O5) | S5: =SUMIFS(E:E,$A:$A,$O5) | T5: =SUMIFS(F:F,$A:$A,$O5) | U5: =SUMIFS(G:G,$A:$A,$O5) | V5: =SUMIFS(H:H,$A:$A,$O5) | W5: =SUMIFS(I:I,$A:$A,$O5) | X5: =SUMIFS(J:J,$A:$A,$O5) | Y5: =SUMIFS(K:K,$A:$A,$O5) | Z5: =SUMIFS(L:L,$A:$A,$O5) | AA5: =SUMIFS(M:M,$A:$A,$O5)
A6: =IFERROR((IF(((IFERROR((FIND(".",I!A4)),0))>1),(MID(I!A4,((FIND(".",I!A4))-2),5)),(MID(I!A4,((FIND(" - ",I!A4))-2),2)))),"-") | B6: =IFERROR(IF($A6="-","null",I!B4),"null") | C6: =IFERROR(IF($A6="-","null",I!C4),"null") | D6: =IFERROR(IF($A6="-","null",I!D4),"null") | E6: =IFERROR(IF($A6="-","null",I!E4),"null") | F6: =IFERROR(IF($A6="-","null",I!F4),"null") | G6: =IFERROR(IF($A6="-","null",I!G4),"null") | H6: =IFERROR(IF($A6="-","null",I!H4),"null") | I6: =IFERROR(IF($A6="-","null",I!I4),"null") | ... M6: =IFERROR(IF($A6="-","null",I!M4),"null") | O6: 10.04 | P6: =SUMIFS(B:B,$A:$A,$O6) | Q6: =SUMIFS(C:C,$A:$A,$O6) | R6: =SUMIFS(D:D,$A:$A,$O6) | S6: =SUMIFS(E:E,$A:$A,$O6) | T6: =SUMIFS(F:F,$A:$A,$O6) | U6: =SUMIFS(G:G,$A:$A,$O6) | V6: =SUMIFS(H:H,$A:$A,$O6) | W6: =SUMIFS(I:I,$A:$A,$O6) | X6: =SUMIFS(J:J,$A:$A,$O6) | Y6: =SUMIFS(K:K,$A:$A,$O6) | Z6: =SUMIFS(L:L,$A:$A,$O6) | AA6: =SUMIFS(M:M,$A:$A,$O6)
A7: =IFERROR((IF(((IFERROR((FIND(".",I!A5)),0))>1),(MID(I!A5,((FIND(".",I!A5))-2),5)),(MID(I!A5,((FIND(" - ",I!A5))-2),2)))),"-") | B7: =IFERROR(IF($A7="-","null",I!B5),"null") | C7: =IFERROR(IF($A7="-","null",I!C5),"null") | D7: =IFERROR(IF($A7="-","null",I!D5),"null") | E7: =IFERROR(IF($A7="-","null",I!E5),"null") | F7: =IFERROR(IF($A7="-","null",I!F5),"null") | G7: =IFERROR(IF($A7="-","null",I!G5),"null") | H7: =IFERROR(IF($A7="-","null",I!H5),"null") | I7: =IFERROR(IF($A7="-","null",I!I5),"null") | ... M7: =IFERROR(IF($A7="-","null",I!M5),"null") | O7: 10.06 | P7: =SUMIFS(B:B,$A:$A,$O7) | Q7: =SUMIFS(C:C,$A:$A,$O7) | R7: =SUMIFS(D:D,$A:$A,$O7) | S7: =SUMIFS(E:E,$A:$A,$O7) | T7: =SUMIFS(F:F,$A:$A,$O7) | U7: =SUMIFS(G:G,$A:$A,$O7) | V7: =SUMIFS(H:H,$A:$A,$O7) | W7: =SUMIFS(I:I,$A:$A,$O7) | X7: =SUMIFS(J:J,$A:$A,$O7) | Y7: =SUMIFS(K:K,$A:$A,$O7) | Z7: =SUMIFS(L:L,$A:$A,$O7) | AA7: =SUMIFS(M:M,$A:$A,$O7)
A8: =IFERROR((IF(((IFERROR((FIND(".",I!A6)),0))>1),(MID(I!A6,((FIND(".",I!A6))-2),5)),(MID(I!A6,((FIND(" - ",I!A6))-2),2)))),"-") | B8: =IFERROR(IF($A8="-","null",I!B6),"null") | C8: =IFERROR(IF($A8="-","null",I!C6),"null") | D8: =IFERROR(IF($A8="-","null",I!D6),"null") | E8: =IFERROR(IF($A8="-","null",I!E6),"null") | F8: =IFERROR(IF($A8="-","null",I!F6),"null") | G8: =IFERROR(IF($A8="-","null",I!G6),"null") | H8: =IFERROR(IF($A8="-","null",I!H6),"null") | I8: =IFERROR(IF($A8="-","null",I!I6),"null") | ... M8: =IFERROR(IF($A8="-","null",I!M6),"null") | O8: 10.07 | P8: =SUMIFS(B:B,$A:$A,$O8) | Q8: =SUMIFS(C:C,$A:$A,$O8) | R8: =SUMIFS(D:D,$A:$A,$O8) | S8: =SUMIFS(E:E,$A:$A,$O8) | T8: =SUMIFS(F:F,$A:$A,$O8) | U8: =SUMIFS(G:G,$A:$A,$O8) | V8: =SUMIFS(H:H,$A:$A,$O8) | W8: =SUMIFS(I:I,$A:$A,$O8) | X8: =SUMIFS(J:J,$A:$A,$O8) | Y8: =SUMIFS(K:K,$A:$A,$O8) | Z8: =SUMIFS(L:L,$A:$A,$O8) | AA8: =SUMIFS(M:M,$A:$A,$O8)
A9: =IFERROR((IF(((IFERROR((FIND(".",I!A7)),0))>1),(MID(I!A7,((FIND(".",I!A7))-2),5)),(MID(I!A7,((FIND(" - ",I!A7))-2),2)))),"-") | B9: =IFERROR(IF($A9="-","null",I!B7),"null") | C9: =IFERROR(IF($A9="-","null",I!C7),"null") | D9: =IFERROR(IF($A9="-","null",I!D7),"null") | E9: =IFERROR(IF($A9="-","null",I!E7),"null") | F9: =IFERROR(IF($A9="-","null",I!F7),"null") | G9: =IFERROR(IF($A9="-","null",I!G7),"null") | H9: =IFERROR(IF($A9="-","null",I!H7),"null") | I9: =IFERROR(IF($A9="-","null",I!I7),"null") | ... M9: =IFERROR(IF($A9="-","null",I!M7),"null") | O9: 10.08 | P9: =SUMIFS(B:B,$A:$A,$O9) | Q9: =SUMIFS(C:C,$A:$A,$O9) | R9: =SUMIFS(D:D,$A:$A,$O9) | S9: =SUMIFS(E:E,$A:$A,$O9) | T9: =SUMIFS(F:F,$A:$A,$O9) | U9: =SUMIFS(G:G,$A:$A,$O9) | V9: =SUMIFS(H:H,$A:$A,$O9) | W9: =SUMIFS(I:I,$A:$A,$O9) | X9: =SUMIFS(J:J,$A:$A,$O9) | Y9: =SUMIFS(K:K,$A:$A,$O9) | Z9: =SUMIFS(L:L,$A:$A,$O9) | AA9: =SUMIFS(M:M,$A:$A,$O9)
A10: =IFERROR((IF(((IFERROR((FIND(".",I!A8)),0))>1),(MID(I!A8,((FIND(".",I!A8))-2),5)),(MID(I!A8,((FIND(" - ",I!A8))-2),2)))),"-") | B10: =IFERROR(IF($A10="-","null",I!B8),"null") | C10: =IFERROR(IF($A10="-","null",I!C8),"null") | D10: =IFERROR(IF($A10="-","null",I!D8),"null") | E10: =IFERROR(IF($A10="-","null",I!E8),"null") | F10: =IFERROR(IF($A10="-","null",I!F8),"null") | G10: =IFERROR(IF($A10="-","null",I!G8),"null") | H10: =IFERROR(IF($A10="-","null",I!H8),"null") | I10: =IFERROR(IF($A10="-","null",I!I8),"null") | ... M10: =IFERROR(IF($A10="-","null",I!M8),"null") | O10: 20.01 | P10: =SUMIFS(B:B,$A:$A,$O10) | Q10: =SUMIFS(C:C,$A:$A,$O10) | R10: =SUMIFS(D:D,$A:$A,$O10) | S10: =SUMIFS(E:E,$A:$A,$O10) | T10: =SUMIFS(F:F,$A:$A,$O10) | U10: =SUMIFS(G:G,$A:$A,$O10) | V10: =SUMIFS(H:H,$A:$A,$O10) | W10: =SUMIFS(I:I,$A:$A,$O10) | X10: =SUMIFS(J:J,$A:$A,$O10) | Y10: =SUMIFS(K:K,$A:$A,$O10) | Z10: =SUMIFS(L:L,$A:$A,$O10) | AA10: =SUMIFS(M:M,$A:$A,$O10)
A11: =IFERROR((IF(((IFERROR((FIND(".",I!A9)),0))>1),(MID(I!A9,((FIND(".",I!A9))-2),5)),(MID(I!A9,((FIND(" - ",I!A9))-2),2)))),"-") | B11: =IFERROR(IF($A11="-","null",I!B9),"null") | C11: =IFERROR(IF($A11="-","null",I!C9),"null") | D11: =IFERROR(IF($A11="-","null",I!D9),"null") | E11: =IFERROR(IF($A11="-","null",I!E9),"null") | F11: =IFERROR(IF($A11="-","null",I!F9),"null") | G11: =IFERROR(IF($A11="-","null",I!G9),"null") | H11: =IFERROR(IF($A11="-","null",I!H9),"null") | I11: =IFERROR(IF($A11="-","null",I!I9),"null") | ... M11: =IFERROR(IF($A11="-","null",I!M9),"null") | O11: 20.04 | P11: =SUMIFS(B:B,$A:$A,$O11) | Q11: =SUMIFS(C:C,$A:$A,$O11) | R11: =SUMIFS(D:D,$A:$A,$O11) | S11: =SUMIFS(E:E,$A:$A,$O11) | T11: =SUMIFS(F:F,$A:$A,$O11) | U11: =SUMIFS(G:G,$A:$A,$O11) | V11: =SUMIFS(H:H,$A:$A,$O11) | W11: =SUMIFS(I:I,$A:$A,$O11) | X11: =SUMIFS(J:J,$A:$A,$O11) | Y11: =SUMIFS(K:K,$A:$A,$O11) | Z11: =SUMIFS(L:L,$A:$A,$O11) | AA11: =SUMIFS(M:M,$A:$A,$O11)
A12: =IFERROR((IF(((IFERROR((FIND(".",I!A10)),0))>1),(MID(I!A10,((FIND(".",I!A10))-2),5)),(MID(I!A10,((FIND(" - ",I!A10))-2),2)))),"-") | B12: =IFERROR(IF($A12="-","null",I!B10),"null") | C12: =IFERROR(IF($A12="-","null",I!C10),"null") | D12: =IFERROR(IF($A12="-","null",I!D10),"null") | E12: =IFERROR(IF($A12="-","null",I!E10),"null") | F12: =IFERROR(IF($A12="-","null",I!F10),"null") | G12: =IFERROR(IF($A12="-","null",I!G10),"null") | H12: =IFERROR(IF($A12="-","null",I!H10),"null") | I12: =IFERROR(IF($A12="-","null",I!I10),"null") | ... M12: =IFERROR(IF($A12="-","null",I!M10),"null") | O12: 20.05 | P12: =SUMIFS(B:B,$A:$A,$O12) | Q12: =SUMIFS(C:C,$A:$A,$O12) | R12: =SUMIFS(D:D,$A:$A,$O12) | S12: =SUMIFS(E:E,$A:$A,$O12) | T12: =SUMIFS(F:F,$A:$A,$O12) | U12: =SUMIFS(G:G,$A:$A,$O12) | V12: =SUMIFS(H:H,$A:$A,$O12) | W12: =SUMIFS(I:I,$A:$A,$O12) | X12: =SUMIFS(J:J,$A:$A,$O12) | Y12: =SUMIFS(K:K,$A:$A,$O12) | Z12: =SUMIFS(L:L,$A:$A,$O12) | AA12: =SUMIFS(M:M,$A:$A,$O12)
A13: =IFERROR((IF(((IFERROR((FIND(".",I!A11)),0))>1),(MID(I!A11,((FIND(".",I!A11))-2),5)),(MID(I!A11,((FIND(" - ",I!A11))-2),2)))),"-") | B13: =IFERROR(IF($A13="-","null",I!B11),"null") | C13: =IFERROR(IF($A13="-","null",I!C11),"null") | D13: =IFERROR(IF($A13="-","null",I!D11),"null") | E13: =IFERROR(IF($A13="-","null",I!E11),"null") | F13: =IFERROR(IF($A13="-","null",I!F11),"null") | G13: =IFERROR(IF($A13="-","null",I!G11),"null") | H13: =IFERROR(IF($A13="-","null",I!H11),"null") | I13: =IFERROR(IF($A13="-","null",I!I11),"null") | ... M13: =IFERROR(IF($A13="-","null",I!M11),"null") | O13: 21.01 | P13: =SUMIFS(B:B,$A:$A,$O13) | Q13: =SUMIFS(C:C,$A:$A,$O13) | R13: =SUMIFS(D:D,$A:$A,$O13) | S13: =SUMIFS(E:E,$A:$A,$O13) | T13: =SUMIFS(F:F,$A:$A,$O13) | U13: =SUMIFS(G:G,$A:$A,$O13) | V13: =SUMIFS(H:H,$A:$A,$O13) | W13: =SUMIFS(I:I,$A:$A,$O13) | X13: =SUMIFS(J:J,$A:$A,$O13) | Y13: =SUMIFS(K:K,$A:$A,$O13) | Z13: =SUMIFS(L:L,$A:$A,$O13) | AA13: =SUMIFS(M:M,$A:$A,$O13)
A14: =IFERROR((IF(((IFERROR((FIND(".",I!A12)),0))>1),(MID(I!A12,((FIND(".",I!A12))-2),5)),(MID(I!A12,((FIND(" - ",I!A12))-2),2)))),"-") | B14: =IFERROR(IF($A14="-","null",I!B12),"null") | C14: =IFERROR(IF($A14="-","null",I!C12),"null") | D14: =IFERROR(IF($A14="-","null",I!D12),"null") | E14: =IFERROR(IF($A14="-","null",I!E12),"null") | F14: =IFERROR(IF($A14="-","null",I!F12),"null") | G14: =IFERROR(IF($A14="-","null",I!G12),"null") | H14: =IFERROR(IF($A14="-","null",I!H12),"null") | I14: =IFERROR(IF($A14="-","null",I!I12),"null") | ... M14: =IFERROR(IF($A14="-","null",I!M12),"null") | O14: 21.02 | P14: =SUMIFS(B:B,$A:$A,$O14) | Q14: =SUMIFS(C:C,$A:$A,$O14) | R14: =SUMIFS(D:D,$A:$A,$O14) | S14: =SUMIFS(E:E,$A:$A,$O14) | T14: =SUMIFS(F:F,$A:$A,$O14) | U14: =SUMIFS(G:G,$A:$A,$O14) | V14: =SUMIFS(H:H,$A:$A,$O14) | W14: =SUMIFS(I:I,$A:$A,$O14) | X14: =SUMIFS(J:J,$A:$A,$O14) | Y14: =SUMIFS(K:K,$A:$A,$O14) | Z14: =SUMIFS(L:L,$A:$A,$O14) | AA14: =SUMIFS(M:M,$A:$A,$O14)
... A175: =IFERROR((IF(((IFERROR((FIND(".",I!A173)),0))>1),(MID(I!A173,((FIND(".",I!A173))-2),5)),(MID(I!A173,((FIND(" - ",I!A173))-2),2)))),"-") | B175: =IFERROR(IF($A175="-","null",I!B173),"null") | C175: =IFERROR(IF($A175="-","null",I!C173),"null") | D175: =IFERROR(IF($A175="-","null",I!D173),"null") | E175: =IFERROR(IF($A175="-","null",I!E173),"null") | F175: =IFERROR(IF($A175="-","null",I!F173),"null") | G175: =IFERROR(IF($A175="-","null",I!G173),"null") | H175: =IFERROR(IF($A175="-","null",I!H173),"null") | I175: =IFERROR(IF($A175="-","null",I!I173),"null") | ... M175: =IFERROR(IF($A175="-","null",I!M173),"null") | O175: 50.02 | P175: =SUMIFS(B:B,$A:$A,$O175) | Q175: =SUMIFS(C:C,$A:$A,$O175) | R175: =SUMIFS(D:D,$A:$A,$O175) | S175: =SUMIFS(E:E,$A:$A,$O175) | T175: =SUMIFS(F:F,$A:$A,$O175) | U175: =SUMIFS(G:G,$A:$A,$O175) | V175: =SUMIFS(H:H,$A:$A,$O175) | W175: =SUMIFS(I:I,$A:$A,$O175) | X175: =SUMIFS(J:J,$A:$A,$O175) | Y175: =SUMIFS(K:K,$A:$A,$O175) | Z175: =SUMIFS(L:L,$A:$A,$O175) | AA175: =SUMIFS(M:M,$A:$A,$O175)
A176: =IFERROR((IF(((IFERROR((FIND(".",I!#REF!)),0))>1),(MID(I!#REF!,((FIND(".",I!#REF!))-2),5)),(MID(I!#REF!,((FIND(" - ",I!#REF!))-2),2)))),"-") | B176: =IFERROR(IF($A176="-","null",I!#REF!),"null") | C176: =IFERROR(IF($A176="-","null",I!#REF!),"null") | D176: =IFERROR(IF($A176="-","null",I!#REF!),"null") | E176: =IFERROR(IF($A176="-","null",I!#REF!),"null") | F176: =IFERROR(IF($A176="-","null",I!#REF!),"null") | G176: =IFERROR(IF($A176="-","null",I!#REF!),"null") | H176: =IFERROR(IF($A176="-","null",I!#REF!),"null") | I176: =IFERROR(IF($A176="-","null",I!#REF!),"null") | ... M176: =IFERROR(IF($A176="-","null",I!#REF!),"null") | O176: 50.03 | P176: =SUMIFS(B:B,$A:$A,$O176) | Q176: =SUMIFS(C:C,$A:$A,$O176) | R176: =SUMIFS(D:D,$A:$A,$O176) | S176: =SUMIFS(E:E,$A:$A,$O176) | T176: =SUMIFS(F:F,$A:$A,$O176) | U176: =SUMIFS(G:G,$A:$A,$O176) | V176: =SUMIFS(H:H,$A:$A,$O176) | W176: =SUMIFS(I:I,$A:$A,$O176) | X176: =SUMIFS(J:J,$A:$A,$O176) | Y176: =SUMIFS(K:K,$A:$A,$O176) | Z176: =SUMIFS(L:L,$A:$A,$O176) | AA176: =SUMIFS(M:M,$A:$A,$O176)
A177: =IFERROR((IF(((IFERROR((FIND(".",I!#REF!)),0))>1),(MID(I!#REF!,((FIND(".",I!#REF!))-2),5)),(MID(I!#REF!,((FIND(" - ",I!#REF!))-2),2)))),"-") | B177: =IFERROR(IF($A177="-","null",I!#REF!),"null") | C177: =IFERROR(IF($A177="-","null",I!#REF!),"null") | D177: =IFERROR(IF($A177="-","null",I!#REF!),"null") | E177: =IFERROR(IF($A177="-","null",I!#REF!),"null") | F177: =IFERROR(IF($A177="-","null",I!#REF!),"null") | G177: =IFERROR(IF($A177="-","null",I!#REF!),"null") | H177: =IFERROR(IF($A177="-","null",I!#REF!),"null") | I177: =IFERROR(IF($A177="-","null",I!#REF!),"null") | ... M177: =IFERROR(IF($A177="-","null",I!#REF!),"null") | O177: 50.04 | P177: =SUMIFS(B:B,$A:$A,$O177) | Q177: =SUMIFS(C:C,$A:$A,$O177) | R177: =SUMIFS(D:D,$A:$A,$O177) | S177: =SUMIFS(E:E,$A:$A,$O177) | T177: =SUMIFS(F:F,$A:$A,$O177) | U177: =SUMIFS(G:G,$A:$A,$O177) | V177: =SUMIFS(H:H,$A:$A,$O177) | W177: =SUMIFS(I:I,$A:$A,$O177) | X177: =SUMIFS(J:J,$A:$A,$O177) | Y177: =SUMIFS(K:K,$A:$A,$O177) | Z177: =SUMIFS(L:L,$A:$A,$O177) | AA177: =SUMIFS(M:M,$A:$A,$O177)
A178: =IFERROR((IF(((IFERROR((FIND(".",I!#REF!)),0))>1),(MID(I!#REF!,((FIND(".",I!#REF!))-2),5)),(MID(I!#REF!,((FIND(" - ",I!#REF!))-2),2)))),"-") | B178: =IFERROR(IF($A178="-","null",I!#REF!),"null") | C178: =IFERROR(IF($A178="-","null",I!#REF!),"null") | D178: =IFERROR(IF($A178="-","null",I!#REF!),"null") | E178: =IFERROR(IF($A178="-","null",I!#REF!),"null") | F178: =IFERROR(IF($A178="-","null",I!#REF!),"null") | G178: =IFERROR(IF($A178="-","null",I!#REF!),"null") | H178: =IFERROR(IF($A178="-","null",I!#REF!),"null") | I178: =IFERROR(IF($A178="-","null",I!#REF!),"null") | ... M178: =IFERROR(IF($A178="-","null",I!#REF!),"null") | O178: 50.05 | P178: =SUMIFS(B:B,$A:$A,$O178) | Q178: =SUMIFS(C:C,$A:$A,$O178) | R178: =SUMIFS(D:D,$A:$A,$O178) | S178: =SUMIFS(E:E,$A:$A,$O178) | T178: =SUMIFS(F:F,$A:$A,$O178) | U178: =SUMIFS(G:G,$A:$A,$O178) | V178: =SUMIFS(H:H,$A:$A,$O178) | W178: =SUMIFS(I:I,$A:$A,$O178) | X178: =SUMIFS(J:J,$A:$A,$O178) | Y178: =SUMIFS(K:K,$A:$A,$O178) | Z178: =SUMIFS(L:L,$A:$A,$O178) | AA178: =SUMIFS(M:M,$A:$A,$O178)
A179: =IFERROR((IF(((IFERROR((FIND(".",I!#REF!)),0))>1),(MID(I!#REF!,((FIND(".",I!#REF!))-2),5)),(MID(I!#REF!,((FIND(" - ",I!#REF!))-2),2)))),"-") | B179: =IFERROR(IF($A179="-","null",I!#REF!),"null") | C179: =IFERROR(IF($A179="-","null",I!#REF!),"null") | D179: =IFERROR(IF($A179="-","null",I!#REF!),"null") | E179: =IFERROR(IF($A179="-","null",I!#REF!),"null") | F179: =IFERROR(IF($A179="-","null",I!#REF!),"null") | G179: =IFERROR(IF($A179="-","null",I!#REF!),"null") | H179: =IFERROR(IF($A179="-","null",I!#REF!),"null") | I179: =IFERROR(IF($A179="-","null",I!#REF!),"null") | ... M179: =IFERROR(IF($A179="-","null",I!#REF!),"null") | O179: 50.06 | P179: =SUMIFS(B:B,$A:$A,$O179) | Q179: =SUMIFS(C:C,$A:$A,$O179) | R179: =SUMIFS(D:D,$A:$A,$O179) | S179: =SUMIFS(E:E,$A:$A,$O179) | T179: =SUMIFS(F:F,$A:$A,$O179) | U179: =SUMIFS(G:G,$A:$A,$O179) | V179: =SUMIFS(H:H,$A:$A,$O179) | W179: =SUMIFS(I:I,$A:$A,$O179) | X179: =SUMIFS(J:J,$A:$A,$O179) | Y179: =SUMIFS(K:K,$A:$A,$O179) | Z179: =SUMIFS(L:L,$A:$A,$O179) | AA179: =SUMIFS(M:M,$A:$A,$O179)
A180: =IFERROR((IF(((IFERROR((FIND(".",I!#REF!)),0))>1),(MID(I!#REF!,((FIND(".",I!#REF!))-2),5)),(MID(I!#REF!,((FIND(" - ",I!#REF!))-2),2)))),"-") | B180: =IFERROR(IF($A180="-","null",I!#REF!),"null") | C180: =IFERROR(IF($A180="-","null",I!#REF!),"null") | D180: =IFERROR(IF($A180="-","null",I!#REF!),"null") | E180: =IFERROR(IF($A180="-","null",I!#REF!),"null") | F180: =IFERROR(IF($A180="-","null",I!#REF!),"null") | G180: =IFERROR(IF($A180="-","null",I!#REF!),"null") | H180: =IFERROR(IF($A180="-","null",I!#REF!),"null") | I180: =IFERROR(IF($A180="-","null",I!#REF!),"null") | ... M180: =IFERROR(IF($A180="-","null",I!#REF!),"null") | O180: 51.01 | P180: =SUMIFS(B:B,$A:$A,$O180) | Q180: =SUMIFS(C:C,$A:$A,$O180) | R180: =SUMIFS(D:D,$A:$A,$O180) | S180: =SUMIFS(E:E,$A:$A,$O180) | T180: =SUMIFS(F:F,$A:$A,$O180) | U180: =SUMIFS(G:G,$A:$A,$O180) | V180: =SUMIFS(H:H,$A:$A,$O180) | W180: =SUMIFS(I:I,$A:$A,$O180) | X180: =SUMIFS(J:J,$A:$A,$O180) | Y180: =SUMIFS(K:K,$A:$A,$O180) | Z180: =SUMIFS(L:L,$A:$A,$O180) | AA180: =SUMIFS(M:M,$A:$A,$O180)
A181: =IFERROR((IF(((IFERROR((FIND(".",I!#REF!)),0))>1),(MID(I!#REF!,((FIND(".",I!#REF!))-2),5)),(MID(I!#REF!,((FIND(" - ",I!#REF!))-2),2)))),"-") | B181: =IFERROR(IF($A181="-","null",I!#REF!),"null") | C181: =IFERROR(IF($A181="-","null",I!#REF!),"null") | D181: =IFERROR(IF($A181="-","null",I!#REF!),"null") | E181: =IFERROR(IF($A181="-","null",I!#REF!),"null") | F181: =IFERROR(IF($A181="-","null",I!#REF!),"null") | G181: =IFERROR(IF($A181="-","null",I!#REF!),"null") | H181: =IFERROR(IF($A181="-","null",I!#REF!),"null") | I181: =IFERROR(IF($A181="-","null",I!#REF!),"null") | ... M181: =IFERROR(IF($A181="-","null",I!#REF!),"null") | O181: 51.02 | P181: =SUMIFS(B:B,$A:$A,$O181) | Q181: =SUMIFS(C:C,$A:$A,$O181) | R181: =SUMIFS(D:D,$A:$A,$O181) | S181: =SUMIFS(E:E,$A:$A,$O181) | T181: =SUMIFS(F:F,$A:$A,$O181) | U181: =SUMIFS(G:G,$A:$A,$O181) | V181: =SUMIFS(H:H,$A:$A,$O181) | W181: =SUMIFS(I:I,$A:$A,$O181) | X181: =SUMIFS(J:J,$A:$A,$O181) | Y181: =SUMIFS(K:K,$A:$A,$O181) | Z181: =SUMIFS(L:L,$A:$A,$O181) | AA181: =SUMIFS(M:M,$A:$A,$O181)
A182: =IFERROR((IF(((IFERROR((FIND(".",I!#REF!)),0))>1),(MID(I!#REF!,((FIND(".",I!#REF!))-2),5)),(MID(I!#REF!,((FIND(" - ",I!#REF!))-2),2)))),"-") | B182: =IFERROR(IF($A182="-","null",I!#REF!),"null") | C182: =IFERROR(IF($A182="-","null",I!#REF!),"null") | D182: =IFERROR(IF($A182="-","null",I!#REF!),"null") | E182: =IFERROR(IF($A182="-","null",I!#REF!),"null") | F182: =IFERROR(IF($A182="-","null",I!#REF!),"null") | G182: =IFERROR(IF($A182="-","null",I!#REF!),"null") | H182: =IFERROR(IF($A182="-","null",I!#REF!),"null") | I182: =IFERROR(IF($A182="-","null",I!#REF!),"null") | ... M182: =IFERROR(IF($A182="-","null",I!#REF!),"null") | O182: 51.03 | P182: =SUMIFS(B:B,$A:$A,$O182) | Q182: =SUMIFS(C:C,$A:$A,$O182) | R182: =SUMIFS(D:D,$A:$A,$O182) | S182: =SUMIFS(E:E,$A:$A,$O182) | T182: =SUMIFS(F:F,$A:$A,$O182) | U182: =SUMIFS(G:G,$A:$A,$O182) | V182: =SUMIFS(H:H,$A:$A,$O182) | W182: =SUMIFS(I:I,$A:$A,$O182) | X182: =SUMIFS(J:J,$A:$A,$O182) | Y182: =SUMIFS(K:K,$A:$A,$O182) | Z182: =SUMIFS(L:L,$A:$A,$O182) | AA182: =SUMIFS(M:M,$A:$A,$O182)
A183: =IFERROR((IF(((IFERROR((FIND(".",I!#REF!)),0))>1),(MID(I!#REF!,((FIND(".",I!#REF!))-2),5)),(MID(I!#REF!,((FIND(" - ",I!#REF!))-2),2)))),"-") | B183: =IFERROR(IF($A183="-","null",I!#REF!),"null") | C183: =IFERROR(IF($A183="-","null",I!#REF!),"null") | D183: =IFERROR(IF($A183="-","null",I!#REF!),"null") | E183: =IFERROR(IF($A183="-","null",I!#REF!),"null") | F183: =IFERROR(IF($A183="-","null",I!#REF!),"null") | G183: =IFERROR(IF($A183="-","null",I!#REF!),"null") | H183: =IFERROR(IF($A183="-","null",I!#REF!),"null") | I183: =IFERROR(IF($A183="-","null",I!#REF!),"null") | ... M183: =IFERROR(IF($A183="-","null",I!#REF!),"null") | O183: 51.04 | P183: =SUMIFS(B:B,$A:$A,$O183) | Q183: =SUMIFS(C:C,$A:$A,$O183) | R183: =SUMIFS(D:D,$A:$A,$O183) | S183: =SUMIFS(E:E,$A:$A,$O183) | T183: =SUMIFS(F:F,$A:$A,$O183) | U183: =SUMIFS(G:G,$A:$A,$O183) | V183: =SUMIFS(H:H,$A:$A,$O183) | W183: =SUMIFS(I:I,$A:$A,$O183) | X183: =SUMIFS(J:J,$A:$A,$O183) | Y183: =SUMIFS(K:K,$A:$A,$O183) | Z183: =SUMIFS(L:L,$A:$A,$O183) | AA183: =SUMIFS(M:M,$A:$A,$O183)
A184: =IFERROR((IF(((IFERROR((FIND(".",I!#REF!)),0))>1),(MID(I!#REF!,((FIND(".",I!#REF!))-2),5)),(MID(I!#REF!,((FIND(" - ",I!#REF!))-2),2)))),"-") | B184: =IFERROR(IF($A184="-","null",I!#REF!),"null") | C184: =IFERROR(IF($A184="-","null",I!#REF!),"null") | D184: =IFERROR(IF($A184="-","null",I!#REF!),"null") | E184: =IFERROR(IF($A184="-","null",I!#REF!),"null") | F184: =IFERROR(IF($A184="-","null",I!#REF!),"null") | G184: =IFERROR(IF($A184="-","null",I!#REF!),"null") | H184: =IFERROR(IF($A184="-","null",I!#REF!),"null") | I184: =IFERROR(IF($A184="-","null",I!#REF!),"null") | ... M184: =IFERROR(IF($A184="-","null",I!#REF!),"null") | O184: 51.05 | P184: =SUMIFS(B:B,$A:$A,$O184) | Q184: =SUMIFS(C:C,$A:$A,$O184) | R184: =SUMIFS(D:D,$A:$A,$O184) | S184: =SUMIFS(E:E,$A:$A,$O184) | T184: =SUMIFS(F:F,$A:$A,$O184) | U184: =SUMIFS(G:G,$A:$A,$O184) | V184: =SUMIFS(H:H,$A:$A,$O184) | W184: =SUMIFS(I:I,$A:$A,$O184) | X184: =SUMIFS(J:J,$A:$A,$O184) | Y184: =SUMIFS(K:K,$A:$A,$O184) | Z184: =SUMIFS(L:L,$A:$A,$O184) | AA184: =SUMIFS(M:M,$A:$A,$O184)
A185: =IFERROR((IF(((IFERROR((FIND(".",I!#REF!)),0))>1),(MID(I!#REF!,((FIND(".",I!#REF!))-2),5)),(MID(I!#REF!,((FIND(" - ",I!#REF!))-2),2)))),"-") | B185: =IFERROR(IF($A185="-","null",I!#REF!),"null") | C185: =IFERROR(IF($A185="-","null",I!#REF!),"null") | D185: =IFERROR(IF($A185="-","null",I!#REF!),"null") | E185: =IFERROR(IF($A185="-","null",I!#REF!),"null") | F185: =IFERROR(IF($A185="-","null",I!#REF!),"null") | G185: =IFERROR(IF($A185="-","null",I!#REF!),"null") | H185: =IFERROR(IF($A185="-","null",I!#REF!),"null") | I185: =IFERROR(IF($A185="-","null",I!#REF!),"null") | ... M185: =IFERROR(IF($A185="-","null",I!#REF!),"null") | O185: 51.06 | P185: =SUMIFS(B:B,$A:$A,$O185) | Q185: =SUMIFS(C:C,$A:$A,$O185) | R185: =SUMIFS(D:D,$A:$A,$O185) | S185: =SUMIFS(E:E,$A:$A,$O185) | T185: =SUMIFS(F:F,$A:$A,$O185) | U185: =SUMIFS(G:G,$A:$A,$O185) | V185: =SUMIFS(H:H,$A:$A,$O185) | W185: =SUMIFS(I:I,$A:$A,$O185) | X185: =SUMIFS(J:J,$A:$A,$O185) | Y185: =SUMIFS(K:K,$A:$A,$O185) | Z185: =SUMIFS(L:L,$A:$A,$O185) | AA185: =SUMIFS(M:M,$A:$A,$O185)
A186: =IFERROR((IF(((IFERROR((FIND(".",I!#REF!)),0))>1),(MID(I!#REF!,((FIND(".",I!#REF!))-2),5)),(MID(I!#REF!,((FIND(" - ",I!#REF!))-2),2)))),"-") | B186: =IFERROR(IF($A186="-","null",I!#REF!),"null") | C186: =IFERROR(IF($A186="-","null",I!#REF!),"null") | D186: =IFERROR(IF($A186="-","null",I!#REF!),"null") | E186: =IFERROR(IF($A186="-","null",I!#REF!),"null") | F186: =IFERROR(IF($A186="-","null",I!#REF!),"null") | G186: =IFERROR(IF($A186="-","null",I!#REF!),"null") | H186: =IFERROR(IF($A186="-","null",I!#REF!),"null") | I186: =IFERROR(IF($A186="-","null",I!#REF!),"null") | ... M186: =IFERROR(IF($A186="-","null",I!#REF!),"null") | O186: 51.07 | P186: =SUMIFS(B:B,$A:$A,$O186) | Q186: =SUMIFS(C:C,$A:$A,$O186) | R186: =SUMIFS(D:D,$A:$A,$O186) | S186: =SUMIFS(E:E,$A:$A,$O186) | T186: =SUMIFS(F:F,$A:$A,$O186) | U186: =SUMIFS(G:G,$A:$A,$O186) | V186: =SUMIFS(H:H,$A:$A,$O186) | W186: =SUMIFS(I:I,$A:$A,$O186) | X186: =SUMIFS(J:J,$A:$A,$O186) | Y186: =SUMIFS(K:K,$A:$A,$O186) | Z186: =SUMIFS(L:L,$A:$A,$O186) | AA186: =SUMIFS(M:M,$A:$A,$O186)
A187: =IFERROR((IF(((IFERROR((FIND(".",I!#REF!)),0))>1),(MID(I!#REF!,((FIND(".",I!#REF!))-2),5)),(MID(I!#REF!,((FIND(" - ",I!#REF!))-2),2)))),"-") | B187: =IFERROR(IF($A187="-","null",I!#REF!),"null") | C187: =IFERROR(IF($A187="-","null",I!#REF!),"null") | D187: =IFERROR(IF($A187="-","null",I!#REF!),"null") | E187: =IFERROR(IF($A187="-","null",I!#REF!),"null") | F187: =IFERROR(IF($A187="-","null",I!#REF!),"null") | G187: =IFERROR(IF($A187="-","null",I!#REF!),"null") | H187: =IFERROR(IF($A187="-","null",I!#REF!),"null") | I187: =IFERROR(IF($A187="-","null",I!#REF!),"null") | ... M187: =IFERROR(IF($A187="-","null",I!#REF!),"null") | O187: 51.08 | P187: =SUMIFS(B:B,$A:$A,$O187) | Q187: =SUMIFS(C:C,$A:$A,$O187) | R187: =SUMIFS(D:D,$A:$A,$O187) | S187: =SUMIFS(E:E,$A:$A,$O187) | T187: =SUMIFS(F:F,$A:$A,$O187) | U187: =SUMIFS(G:G,$A:$A,$O187) | V187: =SUMIFS(H:H,$A:$A,$O187) | W187: =SUMIFS(I:I,$A:$A,$O187) | X187: =SUMIFS(J:J,$A:$A,$O187) | Y187: =SUMIFS(K:K,$A:$A,$O187) | Z187: =SUMIFS(L:L,$A:$A,$O187) | AA187: =SUMIFS(M:M,$A:$A,$O187)
... A189: =IFERROR((IF(((IFERROR((FIND(".",I!#REF!)),0))>1),(MID(I!#REF!,((FIND(".",I!#REF!))-2),5)),(MID(I!#REF!,((FIND(" - ",I!#REF!))-2),2)))),"-") | B189: =IFERROR(IF($A189="-","null",I!#REF!),"null") | C189: =IFERROR(IF($A189="-","null",I!#REF!),"null") | D189: =IFERROR(IF($A189="-","null",I!#REF!),"null") | E189: =IFERROR(IF($A189="-","null",I!#REF!),"null") | F189: =IFERROR(IF($A189="-","null",I!#REF!),"null") | G189: =IFERROR(IF($A189="-","null",I!#REF!),"null") | H189: =IFERROR(IF($A189="-","null",I!#REF!),"null") | I189: =IFERROR(IF($A189="-","null",I!#REF!),"null") | ... M189: =IFERROR(IF($A189="-","null",I!#REF!),"null") | O189: 52.02 | P189: =SUMIFS(B:B,$A:$A,$O189) | Q189: =SUMIFS(C:C,$A:$A,$O189) | R189: =SUMIFS(D:D,$A:$A,$O189) | S189: =SUMIFS(E:E,$A:$A,$O189) | T189: =SUMIFS(F:F,$A:$A,$O189) | U189: =SUMIFS(G:G,$A:$A,$O189) | V189: =SUMIFS(H:H,$A:$A,$O189) | W189: =SUMIFS(I:I,$A:$A,$O189) | X189: =SUMIFS(J:J,$A:$A,$O189) | Y189: =SUMIFS(K:K,$A:$A,$O189) | Z189: =SUMIFS(L:L,$A:$A,$O189) | AA189: =SUMIFS(M:M,$A:$A,$O189)
A190: =IFERROR((IF(((IFERROR((FIND(".",I!A174)),0))>1),(MID(I!A174,((FIND(".",I!A174))-2),5)),(MID(I!A174,((FIND(" - ",I!A174))-2),2)))),"-") | B190: =IFERROR(IF($A190="-","null",I!B174),"null") | C190: =IFERROR(IF($A190="-","null",I!C174),"null") | D190: =IFERROR(IF($A190="-","null",I!D174),"null") | E190: =IFERROR(IF($A190="-","null",I!E174),"null") | F190: =IFERROR(IF($A190="-","null",I!F174),"null") | G190: =IFERROR(IF($A190="-","null",I!G174),"null") | H190: =IFERROR(IF($A190="-","null",I!H174),"null") | I190: =IFERROR(IF($A190="-","null",I!I174),"null") | ... M190: =IFERROR(IF($A190="-","null",I!M174),"null") | O190: 52.03 | P190: =SUMIFS(B:B,$A:$A,$O190) | Q190: =SUMIFS(C:C,$A:$A,$O190) | R190: =SUMIFS(D:D,$A:$A,$O190) | S190: =SUMIFS(E:E,$A:$A,$O190) | T190: =SUMIFS(F:F,$A:$A,$O190) | U190: =SUMIFS(G:G,$A:$A,$O190) | V190: =SUMIFS(H:H,$A:$A,$O190) | W190: =SUMIFS(I:I,$A:$A,$O190) | X190: =SUMIFS(J:J,$A:$A,$O190) | Y190: =SUMIFS(K:K,$A:$A,$O190) | Z190: =SUMIFS(L:L,$A:$A,$O190) | AA190: =SUMIFS(M:M,$A:$A,$O190)
A191: =IFERROR((IF(((IFERROR((FIND(".",I!A175)),0))>1),(MID(I!A175,((FIND(".",I!A175))-2),5)),(MID(I!A175,((FIND(" - ",I!A175))-2),2)))),"-") | B191: =IFERROR(IF($A191="-","null",I!B175),"null") | C191: =IFERROR(IF($A191="-","null",I!C175),"null") | D191: =IFERROR(IF($A191="-","null",I!D175),"null") | E191: =IFERROR(IF($A191="-","null",I!E175),"null") | F191: =IFERROR(IF($A191="-","null",I!F175),"null") | G191: =IFERROR(IF($A191="-","null",I!G175),"null") | H191: =IFERROR(IF($A191="-","null",I!H175),"null") | I191: =IFERROR(IF($A191="-","null",I!I175),"null") | ... M191: =IFERROR(IF($A191="-","null",I!M175),"null") | O191: 52.04 | P191: =SUMIFS(B:B,$A:$A,$O191) | Q191: =SUMIFS(C:C,$A:$A,$O191) | R191: =SUMIFS(D:D,$A:$A,$O191) | S191: =SUMIFS(E:E,$A:$A,$O191) | T191: =SUMIFS(F:F,$A:$A,$O191) | U191: =SUMIFS(G:G,$A:$A,$O191) | V191: =SUMIFS(H:H,$A:$A,$O191) | W191: =SUMIFS(I:I,$A:$A,$O191) | X191: =SUMIFS(J:J,$A:$A,$O191) | Y191: =SUMIFS(K:K,$A:$A,$O191) | Z191: =SUMIFS(L:L,$A:$A,$O191) | AA191: =SUMIFS(M:M,$A:$A,$O191)
A192: =IFERROR((IF(((IFERROR((FIND(".",I!A176)),0))>1),(MID(I!A176,((FIND(".",I!A176))-2),5)),(MID(I!A176,((FIND(" - ",I!A176))-2),2)))),"-") | B192: =IFERROR(IF($A192="-","null",I!B176),"null") | C192: =IFERROR(IF($A192="-","null",I!C176),"null") | D192: =IFERROR(IF($A192="-","null",I!D176),"null") | E192: =IFERROR(IF($A192="-","null",I!E176),"null") | F192: =IFERROR(IF($A192="-","null",I!F176),"null") | G192: =IFERROR(IF($A192="-","null",I!G176),"null") | H192: =IFERROR(IF($A192="-","null",I!H176),"null") | I192: =IFERROR(IF($A192="-","null",I!I176),"null") | ... M192: =IFERROR(IF($A192="-","null",I!M176),"null") | O192: 53.01 | P192: =SUMIFS(B:B,$A:$A,$O192) | Q192: =SUMIFS(C:C,$A:$A,$O192) | R192: =SUMIFS(D:D,$A:$A,$O192) | S192: =SUMIFS(E:E,$A:$A,$O192) | T192: =SUMIFS(F:F,$A:$A,$O192) | U192: =SUMIFS(G:G,$A:$A,$O192) | V192: =SUMIFS(H:H,$A:$A,$O192) | W192: =SUMIFS(I:I,$A:$A,$O192) | X192: =SUMIFS(J:J,$A:$A,$O192) | Y192: =SUMIFS(K:K,$A:$A,$O192) | Z192: =SUMIFS(L:L,$A:$A,$O192) | AA192: =SUMIFS(M:M,$A:$A,$O192)
A193: =IFERROR((IF(((IFERROR((FIND(".",I!A177)),0))>1),(MID(I!A177,((FIND(".",I!A177))-2),5)),(MID(I!A177,((FIND(" - ",I!A177))-2),2)))),"-") | B193: =IFERROR(IF($A193="-","null",I!B177),"null") | C193: =IFERROR(IF($A193="-","null",I!C177),"null") | D193: =IFERROR(IF($A193="-","null",I!D177),"null") | E193: =IFERROR(IF($A193="-","null",I!E177),"null") | F193: =IFERROR(IF($A193="-","null",I!F177),"null") | G193: =IFERROR(IF($A193="-","null",I!G177),"null") | H193: =IFERROR(IF($A193="-","null",I!H177),"null") | I193: =IFERROR(IF($A193="-","null",I!I177),"null") | ... M193: =IFERROR(IF($A193="-","null",I!M177),"null") | O193: 53.02 | P193: =SUMIFS(B:B,$A:$A,$O193) | Q193: =SUMIFS(C:C,$A:$A,$O193) | R193: =SUMIFS(D:D,$A:$A,$O193) | S193: =SUMIFS(E:E,$A:$A,$O193) | T193: =SUMIFS(F:F,$A:$A,$O193) | U193: =SUMIFS(G:G,$A:$A,$O193) | V193: =SUMIFS(H:H,$A:$A,$O193) | W193: =SUMIFS(I:I,$A:$A,$O193) | X193: =SUMIFS(J:J,$A:$A,$O193) | Y193: =SUMIFS(K:K,$A:$A,$O193) | Z193: =SUMIFS(L:L,$A:$A,$O193) | AA193: =SUMIFS(M:M,$A:$A,$O193)
A194: =IFERROR((IF(((IFERROR((FIND(".",I!A178)),0))>1),(MID(I!A178,((FIND(".",I!A178))-2),5)),(MID(I!A178,((FIND(" - ",I!A178))-2),2)))),"-") | B194: =IFERROR(IF($A194="-","null",I!B178),"null") | C194: =IFERROR(IF($A194="-","null",I!C178),"null") | D194: =IFERROR(IF($A194="-","null",I!D178),"null") | E194: =IFERROR(IF($A194="-","null",I!E178),"null") | F194: =IFERROR(IF($A194="-","null",I!F178),"null") | G194: =IFERROR(IF($A194="-","null",I!G178),"null") | H194: =IFERROR(IF($A194="-","null",I!H178),"null") | I194: =IFERROR(IF($A194="-","null",I!I178),"null") | ... M194: =IFERROR(IF($A194="-","null",I!M178),"null") | O194: 54.01 | P194: =SUMIFS(B:B,$A:$A,$O194) | Q194: =SUMIFS(C:C,$A:$A,$O194) | R194: =SUMIFS(D:D,$A:$A,$O194) | S194: =SUMIFS(E:E,$A:$A,$O194) | T194: =SUMIFS(F:F,$A:$A,$O194) | U194: =SUMIFS(G:G,$A:$A,$O194) | V194: =SUMIFS(H:H,$A:$A,$O194) | W194: =SUMIFS(I:I,$A:$A,$O194) | X194: =SUMIFS(J:J,$A:$A,$O194) | Y194: =SUMIFS(K:K,$A:$A,$O194) | Z194: =SUMIFS(L:L,$A:$A,$O194) | AA194: =SUMIFS(M:M,$A:$A,$O194)
A195: =IFERROR((IF(((IFERROR((FIND(".",I!A179)),0))>1),(MID(I!A179,((FIND(".",I!A179))-2),5)),(MID(I!A179,((FIND(" - ",I!A179))-2),2)))),"-") | B195: =IFERROR(IF($A195="-","null",I!B179),"null") | C195: =IFERROR(IF($A195="-","null",I!C179),"null") | D195: =IFERROR(IF($A195="-","null",I!D179),"null") | E195: =IFERROR(IF($A195="-","null",I!E179),"null") | F195: =IFERROR(IF($A195="-","null",I!F179),"null") | G195: =IFERROR(IF($A195="-","null",I!G179),"null") | H195: =IFERROR(IF($A195="-","null",I!H179),"null") | I195: =IFERROR(IF($A195="-","null",I!I179),"null") | ... M195: =IFERROR(IF($A195="-","null",I!M179),"null") | O195: 54.02 | P195: =SUMIFS(B:B,$A:$A,$O195) | Q195: =SUMIFS(C:C,$A:$A,$O195) | R195: =SUMIFS(D:D,$A:$A,$O195) | S195: =SUMIFS(E:E,$A:$A,$O195) | T195: =SUMIFS(F:F,$A:$A,$O195) | U195: =SUMIFS(G:G,$A:$A,$O195) | V195: =SUMIFS(H:H,$A:$A,$O195) | W195: =SUMIFS(I:I,$A:$A,$O195) | X195: =SUMIFS(J:J,$A:$A,$O195) | Y195: =SUMIFS(K:K,$A:$A,$O195) | Z195: =SUMIFS(L:L,$A:$A,$O195) | AA195: =SUMIFS(M:M,$A:$A,$O195)
A196: =IFERROR((IF(((IFERROR((FIND(".",I!A180)),0))>1),(MID(I!A180,((FIND(".",I!A180))-2),5)),(MID(I!A180,((FIND(" - ",I!A180))-2),2)))),"-") | B196: =IFERROR(IF($A196="-","null",I!B180),"null") | C196: =IFERROR(IF($A196="-","null",I!C180),"null") | D196: =IFERROR(IF($A196="-","null",I!D180),"null") | E196: =IFERROR(IF($A196="-","null",I!E180),"null") | F196: =IFERROR(IF($A196="-","null",I!F180),"null") | G196: =IFERROR(IF($A196="-","null",I!G180),"null") | H196: =IFERROR(IF($A196="-","null",I!H180),"null") | I196: =IFERROR(IF($A196="-","null",I!I180),"null") | ... M196: =IFERROR(IF($A196="-","null",I!M180),"null") | O196: 54.04 | P196: =SUMIFS(B:B,$A:$A,$O196) | Q196: =SUMIFS(C:C,$A:$A,$O196) | R196: =SUMIFS(D:D,$A:$A,$O196) | S196: =SUMIFS(E:E,$A:$A,$O196) | T196: =SUMIFS(F:F,$A:$A,$O196) | U196: =SUMIFS(G:G,$A:$A,$O196) | V196: =SUMIFS(H:H,$A:$A,$O196) | W196: =SUMIFS(I:I,$A:$A,$O196) | X196: =SUMIFS(J:J,$A:$A,$O196) | Y196: =SUMIFS(K:K,$A:$A,$O196) | Z196: =SUMIFS(L:L,$A:$A,$O196) | AA196: =SUMIFS(M:M,$A:$A,$O196)
A197: =IFERROR((IF(((IFERROR((FIND(".",I!A181)),0))>1),(MID(I!A181,((FIND(".",I!A181))-2),5)),(MID(I!A181,((FIND(" - ",I!A181))-2),2)))),"-") | B197: =IFERROR(IF($A197="-","null",I!B181),"null") | C197: =IFERROR(IF($A197="-","null",I!C181),"null") | D197: =IFERROR(IF($A197="-","null",I!D181),"null") | E197: =IFERROR(IF($A197="-","null",I!E181),"null") | F197: =IFERROR(IF($A197="-","null",I!F181),"null") | G197: =IFERROR(IF($A197="-","null",I!G181),"null") | H197: =IFERROR(IF($A197="-","null",I!H181),"null") | I197: =IFERROR(IF($A197="-","null",I!I181),"null") | ... M197: =IFERROR(IF($A197="-","null",I!M181),"null") | O197: 54.05 | P197: =SUMIFS(B:B,$A:$A,$O197) | Q197: =SUMIFS(C:C,$A:$A,$O197) | R197: =SUMIFS(D:D,$A:$A,$O197) | S197: =SUMIFS(E:E,$A:$A,$O197) | T197: =SUMIFS(F:F,$A:$A,$O197) | U197: =SUMIFS(G:G,$A:$A,$O197) | V197: =SUMIFS(H:H,$A:$A,$O197) | W197: =SUMIFS(I:I,$A:$A,$O197) | X197: =SUMIFS(J:J,$A:$A,$O197) | Y197: =SUMIFS(K:K,$A:$A,$O197) | Z197: =SUMIFS(L:L,$A:$A,$O197) | AA197: =SUMIFS(M:M,$A:$A,$O197)
A198: =IFERROR((IF(((IFERROR((FIND(".",I!A182)),0))>1),(MID(I!A182,((FIND(".",I!A182))-2),5)),(MID(I!A182,((FIND(" - ",I!A182))-2),2)))),"-") | B198: =IFERROR(IF($A198="-","null",I!B182),"null") | C198: =IFERROR(IF($A198="-","null",I!C182),"null") | D198: =IFERROR(IF($A198="-","null",I!D182),"null") | E198: =IFERROR(IF($A198="-","null",I!E182),"null") | F198: =IFERROR(IF($A198="-","null",I!F182),"null") | G198: =IFERROR(IF($A198="-","null",I!G182),"null") | H198: =IFERROR(IF($A198="-","null",I!H182),"null") | I198: =IFERROR(IF($A198="-","null",I!I182),"null") | ... M198: =IFERROR(IF($A198="-","null",I!M182),"null") | O198: 55.01 | P198: =SUMIFS(B:B,$A:$A,$O198) | Q198: =SUMIFS(C:C,$A:$A,$O198) | R198: =SUMIFS(D:D,$A:$A,$O198) | S198: =SUMIFS(E:E,$A:$A,$O198) | T198: =SUMIFS(F:F,$A:$A,$O198) | U198: =SUMIFS(G:G,$A:$A,$O198) | V198: =SUMIFS(H:H,$A:$A,$O198) | W198: =SUMIFS(I:I,$A:$A,$O198) | X198: =SUMIFS(J:J,$A:$A,$O198) | Y198: =SUMIFS(K:K,$A:$A,$O198) | Z198: =SUMIFS(L:L,$A:$A,$O198) | AA198: =SUMIFS(M:M,$A:$A,$O198)
A199: =IFERROR((IF(((IFERROR((FIND(".",I!A183)),0))>1),(MID(I!A183,((FIND(".",I!A183))-2),5)),(MID(I!A183,((FIND(" - ",I!A183))-2),2)))),"-") | B199: =IFERROR(IF($A199="-","null",I!B183),"null") | C199: =IFERROR(IF($A199="-","null",I!C183),"null") | D199: =IFERROR(IF($A199="-","null",I!D183),"null") | E199: =IFERROR(IF($A199="-","null",I!E183),"null") | F199: =IFERROR(IF($A199="-","null",I!F183),"null") | G199: =IFERROR(IF($A199="-","null",I!G183),"null") | H199: =IFERROR(IF($A199="-","null",I!H183),"null") | I199: =IFERROR(IF($A199="-","null",I!I183),"null") | ... M199: =IFERROR(IF($A199="-","null",I!M183),"null") | O199: 55.02 | P199: =SUMIFS(B:B,$A:$A,$O199) | Q199: =SUMIFS(C:C,$A:$A,$O199) | R199: =SUMIFS(D:D,$A:$A,$O199) | S199: =SUMIFS(E:E,$A:$A,$O199) | T199: =SUMIFS(F:F,$A:$A,$O199) | U199: =SUMIFS(G:G,$A:$A,$O199) | V199: =SUMIFS(H:H,$A:$A,$O199) | W199: =SUMIFS(I:I,$A:$A,$O199) | X199: =SUMIFS(J:J,$A:$A,$O199) | Y199: =SUMIFS(K:K,$A:$A,$O199) | Z199: =SUMIFS(L:L,$A:$A,$O199) | AA199: =SUMIFS(M:M,$A:$A,$O199)

Sheet BD
AI3: 9 | AJ3: 10 | AK3: 11 | AL3: 12 | AM3: 13 | AN3: 14 | AO3: 15 | AP3: 16 | AQ3: 17 | AR3: 18 | AS3: 19 | AT3: 20 | AV3: 9 | AW3: 10 | AX3: 11 | AY3: 12 | AZ3: 13 | BA3: 14 | BB3: 15 | BC3: 16 | BD3: 17 | BE3: 18 | BF3: 19 | BG3: 20
A4: Clasf. | B4: Nome da conta | C4: Tipo | D4: Natureza | E4: Grupo de conta | F4: Ativo | G4: Status | I4: 43831 | J4: 43862 | K4: 43891 | L4: 43922 | M4: 43952 | N4: 43983 | O4: 44013 | P4: 44044 | Q4: 44075 | R4: 44105 | S4: 44136 | T4: 44166 | V4: 44197 | W4: 44228 | X4: 44256 | Y4: 44287 | Z4: 44317 | AA4: 44348 | AB4: 44378 | AC4: 44409 | AD4: 44440 | AE4: 44470 | AF4: 44501 | AG4: 44531 | AI4: 44562 | AJ4: 44593 | AK4: 44621 | AL4: 44652 | AM4: 44682 | AN4: 44713 | AO4: 44743 | AP4: 44774 | AQ4: 44805 | AR4: 44835 | AS4: 44866 | AT4: 44896 | AV4: 44927 | AW4: 44958 | AX4: 44986 | AY4: 45017 | AZ4: 45047 | BA4: 45078 | BB4: 45108 | BC4: 45139 | BD4: 45170 | BE4: 45200 | BF4: 45231 | BG4: 45261 | BJ4: 45292 | BK4: 45323 | BL4: 45352 | BM4: 45383 | BN4: 45413 | BO4: 45444 | BP4: 45474 | BQ4: 45505 | BR4: 45536 | BS4: 45566 | BT4: 45597 | BU4: 45627 | BW4: jan/25 | BX4: fev/25 | BY4: mar/25 | BZ4: abr/25 | CA4: mai/25 | CB4: jun/25 | CC4: jul/25 | CD4: ago/25 | CE4: set/25 | CF4: out/25 | CG4: nov/25 | CH4: dez/25
A5: 10.01 | B5: Receita com produto | C5: Analítica | D5: Entrada | E5: =VLOOKUP($A5,PL.C!$B:$F,5,0) | F5: sim | G5: Budget | I5: 0 | J5: 36476 | K5: 42099 | L5: 1778806 | M5: 980903 | N5: 1146964 | O5: 1067595 | P5: 993317 | Q5: 1045459 | R5: 995263 | S5: 809964 | T5: 1083586 | V5: 920566 | W5: 847949 | X5: 1081182 | Y5: 971699 | Z5: 986935 | AA5: 1087558 | AB5: 1124216 | AC5: 1156838 | AD5: 1059419 | AE5: 993808 | AF5: 1098796 | AG5: 1075932 | AI5: 853337 | AJ5: 840528 | AK5: 1260369 | AL5: 1012027 | AM5: 1155106 | AN5: 1181187 | AO5: 1160671 | AP5: 1231074 | AQ5: 1117419 | AR5: 1131961 | AS5: 1242942 | AT5: 1217485 | AV5: 938670.7 | AW5: 924580.8 | AX5: 1386405.9 | AY5: 1113229.7 | AZ5: 1270616.6 | BA5: 1299305.7 | BB5: 1276738.1 | BC5: 1354181.4 | BD5: 1229160.9 | BE5: 1245157.1 | BF5: 1367236.2 | BG5: 1339233.5 | BJ5: 1307373.4 | BK5: 1255054.1 | BL5: 1396844.7 | BM5: 1286710.3 | BN5: 1455097.2 | BO5: 1561691.3 | BP5: 1459685.7 | BQ5: 1553959.8 | BR5: 1460685.5 | BS5: 1505911.7 | BT5: 1438646.5 | BU5: 1533462.2 | BW5: ='Hist. e Proj.'!AV62 | BX5: ='Hist. e Proj.'!AW62 | BY5: ='Hist. e Proj.'!AX62 | BZ5: ='Hist. e Proj.'!AY62 | CA5: ='Hist. e Proj.'!AZ62 | CB5: ='Hist. e Proj.'!BA62 | CC5: ='Hist. e Proj.'!BB62 | CD5: ='Hist. e Proj.'!BC62 | ... CH5: ='Hist. e Proj.'!BG62
A6: 10.02 | B6: Receita com serviço | C6: Analítica | D6: Entrada | E6: =VLOOKUP($A6,PL.C!$B:$F,5,0) | F6: sim | G6: Budget | I6: 0 | J6: 0 | K6: 0 | L6: 0 | M6: 0 | N6: 0 | O6: 0 | P6: 0 | Q6: 37 | R6: 0 | S6: 0 | T6: 0 | V6: 0 | W6: 0 | X6: 0 | Y6: 0 | Z6: 579 | AA6: 0 | AB6: 0 | AC6: 0 | AD6: 0 | AE6: 0 | AF6: 0 | AG6: 0 | AI6: 0 | AJ6: 0 | AK6: 0 | AL6: 0 | AM6: 0 | AN6: 0 | AO6: 0 | AP6: 0 | AQ6: 0 | AR6: 0 | AS6: 0 | AT6: 0 | AV6: 0 | AW6: 0 | AX6: 0 | AY6: 0 | AZ6: 0 | BA6: 0 | BB6: 0 | BC6: 0 | BD6: 0 | BE6: 0 | BF6: 0 | BG6: 0 | BI6: 1.05 | BJ6: 21 | BK6: 0 | BL6: 0 | BM6: 0 | BN6: 0 | BO6: 0 | BP6: 0 | BQ6: 0 | BR6: 0 | BS6: 0 | BT6: 0 | BU6: 0 | BW6: =_xlfn.XLOOKUP($A6,$A$203:$A$399,BJ$203:BJ$399,"Não Existe")*$BI6 | BX6: =_xlfn.SINGLE(_xlfn.XLOOKUP($A6,$A$203:$A$399,BK$203:BK$399,"Não Existe"))*$BI6 | BY6: =_xlfn.SINGLE(_xlfn.XLOOKUP($A6,$A$203:$A$399,BL$203:BL$399,"Não Existe"))*$BI6 | BZ6: =_xlfn.SINGLE(_xlfn.XLOOKUP($A6,$A$203:$A$399,BM$203:BM$399,"Não Existe"))*$BI6 | CA6: =_xlfn.SINGLE(_xlfn.XLOOKUP($A6,$A$203:$A$399,BN$203:BN$399,"Não Existe"))*$BI6 | CB6: =_xlfn.SINGLE(_xlfn.XLOOKUP($A6,$A$203:$A$399,BO$203:BO$399,"Não Existe"))*$BI6 | CC6: =_xlfn.SINGLE(_xlfn.XLOOKUP($A6,$A$203:$A$399,BP$203:BP$399,"Não Existe"))*$BI6 | CD6: =_xlfn.SINGLE(_xlfn.XLOOKUP($A6,$A$203:$A$399,BQ$203:BQ$399,"Não Existe"))*$BI6 | CE6: =_xlfn.SINGLE(_xlfn.XLOOKUP($A6,$A$203:$A$399,BR$203:BR$399,"Não Existe"))*$BI6 | ... CH6: =_xlfn.SINGLE(_xlfn.XLOOKUP($A6,$A$203:$A$399,BU$203:BU$399,"Não Existe"))*$BI6
A7: 10.03 | B7: Outras Receitas | C7: Analítica | D7: Entrada | E7: =VLOOKUP($A7,PL.C!$B:$F,5,0) | F7: sim | G7: Budget | I7: 0 | J7: 0 | K7: 0 | L7: 0 | M7: 0 | N7: 1109 | O7: 1458 | P7: 1835 | Q7: 2850 | R7: 762 | S7: 614 | T7: 2959 | V7: 4039 | W7: 1033 | X7: 1029 | Y7: 997 | Z7: 869 | AA7: 916 | AB7: 1657 | AC7: 764 | AD7: 783 | AE7: 1959 | AF7: 456 | AG7: 612 | AI7: 425 | AJ7: 10862 | AK7: 5968 | AL7: 1002 | AM7: 374 | AN7: 396 | AO7: 389 | AP7: 2848 | AQ7: 1126 | AR7: 6437 | AS7: 2605 | AT7: 3477 | AV7: 447.1 | AW7: 11426.824 | AX7: 6278.336 | AY7: 1054.104 | AZ7: 393.448 | BA7: 416.592 | BB7: 409.228 | BC7: 2996.096 | BD7: 1184.552 | BE7: 6771.724 | BF7: 2740.46 | BG7: 3657.804 | BI7: 1.05 | BJ7: 9691.5 | BK7: 1462.65 | BL7: 2131.5 | BM7: 1544.55 | BN7: 2871.75 | BO7: 1923.6 | BP7: 1386 | BQ7: 7108.5 | BR7: 4737.6 | BS7: 1832.25 | BT7: 0 | BU7: 2891.7 | BW7: =_xlfn.XLOOKUP($A7,$A$203:$A$399,BJ$203:BJ$399,"Não Existe")*$BI7 | BX7: =_xlfn.SINGLE(_xlfn.XLOOKUP($A7,$A$203:$A$399,BK$203:BK$399,"Não Existe"))*$BI7 | BY7: =_xlfn.SINGLE(_xlfn.XLOOKUP($A7,$A$203:$A$399,BL$203:BL$399,"Não Existe"))*$BI7 | BZ7: =_xlfn.SINGLE(_xlfn.XLOOKUP($A7,$A$203:$A$399,BM$203:BM$399,"Não Existe"))*$BI7 | CA7: =_xlfn.SINGLE(_xlfn.XLOOKUP($A7,$A$203:$A$399,BN$203:BN$399,"Não Existe"))*$BI7 | CB7: =_xlfn.SINGLE(_xlfn.XLOOKUP($A7,$A$203:$A$399,BO$203:BO$399,"Não Existe"))*$BI7 | CC7: =_xlfn.SINGLE(_xlfn.XLOOKUP($A7,$A$203:$A$399,BP$203:BP$399,"Não Existe"))*$BI7 | CD7: =_xlfn.SINGLE(_xlfn.XLOOKUP($A7,$A$203:$A$399,BQ$203:BQ$399,"Não Existe"))*$BI7 | CE7: =_xlfn.SINGLE(_xlfn.XLOOKUP($A7,$A$203:$A$399,BR$203:BR$399,"Não Existe"))*$BI7 | ... CH7: =_xlfn.SINGLE(_xlfn.XLOOKUP($A7,$A$203:$A$399,BU$203:BU$399,"Não Existe"))*$BI7
A8: 10.04 | B8: Estorno de Produtos | C8: Analítica | D8: Saída | E8: =VLOOKUP($A8,PL.C!$B:$F,5,0) | F8: sim | G8: Budget | I8: 0 | J8: 0 | K8: 0 | L8: 0 | M8: 0 | N8: 0 | O8: 0 | P8: 0 | Q8: -56 | R8: -10 | S8: 0 | T8: 0 | V8: 0 | W8: 0 | X8: 0 | Y8: 0 | Z8: 0 | AA8: 0 | AB8: 0 | AC8: 0 | AD8: 0 | AE8: 0 | AF8: -268 | AG8: -22 | AI8: 0 | AJ8: 0 | AK8: 0 | AL8: 0 | AM8: 0 | AN8: 0 | AO8: 0 | AP8: 0 | AQ8: 0 | AR8: 0 | AS8: 0 | AT8: 0 | AV8: 0 | AW8: 0 | AX8: 0 | AY8: 0 | AZ8: 0 | BA8: 0 | BB8: 0 | BC8: 0 | BD8: 0 | BE8: 0 | BF8: 0 | BG8: 0 | BI8: 1.05 | BJ8: 0 | BK8: 0 | BL8: 0 | BM8: 0 | BN8: 0 | BO8: 0 | BP8: 0 | BQ8: 0 | BR8: 0 | BS8: 0 | BT8: 0 | BU8: 0 | BW8: =_xlfn.XLOOKUP($A8,$A$203:$A$399,BJ$203:BJ$399,"Não Existe")*$BI8 | BX8: =_xlfn.SINGLE(_xlfn.XLOOKUP($A8,$A$203:$A$399,BK$203:BK$399,"Não Existe"))*$BI8 | BY8: =_xlfn.SINGLE(_xlfn.XLOOKUP($A8,$A$203:$A$399,BL$203:BL$399,"Não Existe"))*$BI8 | BZ8: =_xlfn.SINGLE(_xlfn.XLOOKUP($A8,$A$203:$A$399,BM$203:BM$399,"Não Existe"))*$BI8 | CA8: =_xlfn.SINGLE(_xlfn.XLOOKUP($A8,$A$203:$A$399,BN$203:BN$399,"Não Existe"))*$BI8 | CB8: =_xlfn.SINGLE(_xlfn.XLOOKUP($A8,$A$203:$A$399,BO$203:BO$399,"Não Existe"))*$BI8 | CC8: =_xlfn.SINGLE(_xlfn.XLOOKUP($A8,$A$203:$A$399,BP$203:BP$399,"Não Existe"))*$BI8 | CD8: =_xlfn.SINGLE(_xlfn.XLOOKUP($A8,$A$203:$A$399,BQ$203:BQ$399,"Não Existe"))*$BI8 | CE8: =_xlfn.SINGLE(_xlfn.XLOOKUP($A8,$A$203:$A$399,BR$203:BR$399,"Não Existe"))*$BI8 | ... CH8: =_xlfn.SINGLE(_xlfn.XLOOKUP($A8,$A$203:$A$399,BU$203:BU$399,"Não Existe"))*$BI8
A9: 10.06 | B9: Devolução de produto | C9: Analítica | D9: Saída | E9: =VLOOKUP($A9,PL.C!$B:$F,5,0) | F9: sim | G9: Budget | I9: 0 | J9: -666 | K9: 0 | L9: -224 | M9: 0 | N9: -47 | O9: -870 | P9: -298 | Q9: -139 | R9: -199 | S9: -60 | T9: -898 | V9: -515 | W9: -274 | X9: -440 | Y9: -1154 | Z9: -431 | AA9: -249 | AB9: -181 | AC9: -196 | AD9: -174 | AE9: -346 | AF9: -127 | AG9: -312 | AI9: -323 | AJ9: -589 | AK9: -207 | AL9: -64 | AM9: -446 | AN9: -136 | AO9: -407 | AP9: -530 | AQ9: -96 | AR9: -287 | AS9: -1700 | AT9: -353 | AV9: -339.796 | AW9: -619.628 | AX9: -217.764 | AY9: -67.328 | AZ9: -469.192 | BA9: -143.072 | BB9: -188.308 | BC9: -499.7 | BD9: -100.992 | BE9: -301.924 | BF9: -1788.4 | BG9: -371.356 | BI9: 1.05 | BJ9: -719.25 | BK9: -1050 | BL9: -1641.15 | BM9: -353.85 | BN9: -680.4 | BO9: -1729.35 | BP9: -417.9 | BQ9: -99.75 | BR9: -3006.15 | BS9: -192.15 | BT9: -753.9 | BU9: -2149.35 | BW9: =_xlfn.XLOOKUP($A9,$A$203:$A$399,BJ$203:BJ$399,"Não Existe")*$BI9 | BX9: =_xlfn.SINGLE(_xlfn.XLOOKUP($A9,$A$203:$A$399,BK$203:BK$399,"Não Existe"))*$BI9 | BY9: =_xlfn.SINGLE(_xlfn.XLOOKUP($A9,$A$203:$A$399,BL$203:BL$399,"Não Existe"))*$BI9 | BZ9: =_xlfn.SINGLE(_xlfn.XLOOKUP($A9,$A$203:$A$399,BM$203:BM$399,"Não Existe"))*$BI9 | CA9: =_xlfn.SINGLE(_xlfn.XLOOKUP($A9,$A$203:$A$399,BN$203:BN$399,"Não Existe"))*$BI9 | CB9: =_xlfn.SINGLE(_xlfn.XLOOKUP($A9,$A$203:$A$399,BO$203:BO$399,"Não Existe"))*$BI9 | CC9: =_xlfn.SINGLE(_xlfn.XLOOKUP($A9,$A$203:$A$399,BP$203:BP$399,"Não Existe"))*$BI9 | CD9: =_xlfn.SINGLE(_xlfn.XLOOKUP($A9,$A$203:$A$399,BQ$203:BQ$399,"Não Existe"))*$BI9 | CE9: =_xlfn.SINGLE(_xlfn.XLOOKUP($A9,$A$203:$A$399,BR$203:BR$399,"Não Existe"))*$BI9 | ... CH9: =_xlfn.SINGLE(_xlfn.XLOOKUP($A9,$A$203:$A$399,BU$203:BU$399,"Não Existe"))*$BI9
